Workbook

Sheet 液体
A1: 符号 | B1: 名称 | C1: 单位 | D1: 公式 | E1: 结果
A2: 工艺参数
A3: T | B3: 介质温度 | C3: ℃ | D3: 设计给定 | E3: 40
A4: Q | B4: 体积流量 | C4: m3/h | D4: 设计给定 | E4: 100
A5: P1 | B5: 阀前压力 | C5: KPa | D5: 设计给定 | E5: 4700
A6: P2 | B6: 阀后压力 | C6: KPa | D6: 设计给定 | E6: 2100
A7: ΔP | B7: 阀前后压差 | C7: KPa | D7: ΔP=P1-P2 | E7: =E5-E6 -> 2600
A8: ρ1 | B8: 在P1和T1时的流体密度 | C8: Kg/m3 | D8: 设计给定 | E8: 1000
A9: ρ1/ρ0 | B9: 相对密度（比重） | C9: 比重 | D9: ρ1/ρ0 | E9: =E8/1000 -> 1
A10: ν | B10: 运动粘度 | C10: m2/s | D10: 设计给定
A11: PC | B11: 绝对热力学临界压力 | C11: MPa | D11: 设计给定 | E11: 22.12
A12: Pr | B12: 对比压力 | D12: Pr=P1/Pc | E12: =E5/E11 -> 212.4774
A13: Pv | B13: 入口温度下液体蒸汽的绝对压力 | C13: KPa | D13: 设计给定 | E13: =E110 -> 260.18707
A14: T1 | B14: 入口绝对温度 | C14: K | D14: T1=T+273.15 | E14: =E3+273.15 -> 313.15
A15: Tc | B15: 绝对热力学临界温度 | C15: K | D15: 设计给定 | E15: =273.15+E13 -> 533.33707
A16: 不可压缩流体（液体）Kv计算
A17: C1 | B17: ΔP<FL2(P1-FFPV)时，非阻塞流，无接管 | E17: =E4/E83*SQRT(E9/E7) -> 19.611614
A18: C2 | B18: ΔP<[(FLP/FP)2(P1-FFPV)]时，非阻塞流，带接管 | E18: =E4/E83/E28*SQRT(E9/E7) -> 19.611614
A19: C3 | B19: ΔP≥FL2(P1-FFPV)时，阻塞流 无接管 | E19: =E4/E83/E27*SQRT(E9/(E5-E30*E13)) -> 16.654244
A20: C4 | B20: ΔP≥[(FLP/FP)2(P1-FFPV)]时，阻塞流，带接管 | E20: =E4/E83/E29*SQRT(E9/(E5-E30*E13)) -> 16.654244
A21: C5 | B21: 非紊流（层流和过渡流）时 | E21: =E4/E83/E61*SQRT(E9/E7) -> #DIV/0!
A22: C | B22: 流量系数Kv，Cv | E22: 50
A23: Ci | B23: 用于反复计算的假定流量系数 | D23: Ci=1.3C | E23: =1.3*E22 -> 65
A24: V | B24: 出口流速 | C24: m/s | E24: =E4/0.785/E36^2/3600*1000000 -> 5.5290163
A25: dB | B25: 噪音 | C25: dBA
B26: 流体状态 | D26: 阻塞流、非阻塞流
A27: FL | B27: 无附接管件控制阀的液体压力恢复系数 | D27: 设计给定 | E27: 0.9
A28: FP | B28: 管道几何形状系数 | E28: =1/SQRT(1+E56/E84*(E23/E36^2)^2) -> 1
A29: FLP | B29: 带附接管件控制阀的液体压力恢复系数和管道几何形状系数的复合系数 | E29: =E27/SQRT(1+E27^2/E84*E56/(E23/E36^2)^2) -> 0.9
A30: FF | B30: 液体临界压力比系数 | E30: =0.96-0.28*(E13/E11/1000) -> 0.95670649
A31: 开度计算 | B31: 等百 | C31: % | E31: =(1-LOG10(E34)/LOG10(E38))*100 -> 82.281618
B32: 线性 | C32: % | E32: =(E39-E34)/((E39-1)*E34)*100 -> 48.275862
B33: 快开 | C33: % | E33: =(1-SQRT(E39*(E34-1)/((E39-1)*E34)))*100 -> 28.080505
B34: m | E34: =E40/E22 -> 2
A35: 尺寸规格
A36: d | B36: 公称通径 | C36: mm | D36: 设计给定 | E36: 80
A37: D | B37: 管道内径 | C37: mm | E37: =E41 -> 80
A38: R | B38: 固有可调比-等百分比 | D38: 设计给定 | E38: 50
B39: 固有可调比-线性、快开 | D39: 设计给定 | E39: 30
A40: Kv | B40: 额定Kv | D40: 设计给定 | E40: 100
...

Sheet 可压缩 (4)
A1: 符号 | B1: 名称 | C1: 单位 | D1: 公式 | E1: 结果
A2: 管道概况
A3: D1 | B3: 进口管道规格 | C3: mm | D3: 设计给定 | E3: 50 | F3: 需要做一个英寸和mm的对照表
A4: D1w | B4: 进口管道外径 | C4: mm | D4: 设计给定 | E4: 57
A5: D1T | B5: 进口管道壁厚 | C5: mm | D5: 设计给定 | E5: 3.5
A6: D2 | B6: 出口管道规格 | C6: mm | D6: 设计给定 | E6: 50
A7: D2w | B7: 出口管道外径 | C7: mm | D7: 设计给定 | E7: 57
A8: D2T | B8: 出口管道壁厚 | C8: mm | D8: 设计给定 | E8: 3.5
A9: 工艺参数
B10: 流体属性 | D10: 设计给定 | E10: 蒸汽
A11: T | B11: 介质温度 | D11: 设计给定 | E11: 250 | F11: 液体温度不能高于饱和温度，否则会报错
D12: 单位选择 | E12: ℃
A13: Q | B13: 气体、液体、蒸汽流量 | D13: 设计给定 | E13: 2000
D14: 单位选择 | E14: Kg/h
B15: 两相流气体或蒸汽流量换算 | D15: 设计给定
D16: 单位选择 | E16: Kg/h
A17: P1 | B17: 阀前压力 | C17: KPa | D17: 设计给定 | E17: 1000
A18: P2 | B18: 阀后压力 | C18: KPa | D18: 设计给定 | E18: 500
A19: ΔP | B19: 阀前后压差 | C19: KPa | D19: ΔP=P1-P2 | E19: =E17-E18 -> 500
A20: ρ | B20: 气体、液体、蒸汽、两相流液 体密度 | D20: 设计给定 | E20: 2.54
D21: 单位选择 | E21: Kg/m3
B22: 两相流气体（蒸汽） 密度 | D22: 设计给定
D23: 单位选择 | E23: Kg/m3
A24: ρ/ρ0 | B24: 相对密度（比重） | C24: 比重 | D24: ρ1/ρ0 | E24: =IF(OR(E10="液体",E10="两相流(液体+气体)",E10="两相流(液体+蒸汽)"),E186/1000,"")
A25: M | B25: 分子量 | C25: Kg/Kmol | D25: 气体计算用
A26: Z | B26: 压缩系数 | D26: 气体计算用 | E26: 1
A27: γ | B27: 比热比系数 | D27: 气体计算用，空气为1.4 | E27: 1.3
A28: 粘度 | B28: 运动粘度 v 动力粘度 u | D28: 粘度类型 | E28: 动力粘度 u
D29: 设计给定 | E29: 1 | F29: 未提供参数时，需要设置默认值，或含20℃的水1.005*10-6mPa.S
D30: 粘度单位 | E30: cP
A31: PC | B31: 绝对热力学临界压力 | C31: MPa | D31: 设计给定 | E31: 22.12
A32: Pr | B32: 对比压力 | D32: Pr=P1/Pc | E32: =E17/E31 -> 45.207957
A33: Pv | B33: 入口温度下液体蒸汽的绝对压力 | C33: KPa | D33: 设计给定 | E33: =E197 -> 3976.0037
A34: T1 | B34: 入口绝对温度 | C34: K | D34: T1=T+273.15 | E34: =IF(E12="℃",E11+273.15,IF(E12="K",E11)) -> 523.15
A35: t | B35: 液体饱和温度 | C35: ℃ | D35: 液体温度不能高于饱和温度，否则会报错 | E35: =E198 -> 179.8125
A36: 阀门参数
B37: 阀门类型 | D37: 设计给定 | E37: IQ10
B38: 阀芯结构 | D38: 设计给定 | E38: 标准型
A39: DN | B39: 口径 | C39: mm | D39: 设计给定 | E39: 50
A40: PN | B40: 压力等级 | C40: MPa/LB | D40: 设计给定 | E40: 1.6
...

Sheet Kv计算
A1: 编码 | B1: 符号 | C1: 名称 | D1: 结果
B2: 管道概况
A3: 1200001 | B3: D1 | C3: 进口管道规格 | E3: 需要做一个英寸和mm的对照表
A4: 1200002 | B4: D1w | C4: 进口管道外径
A5: 1200003 | B5: D1T | C5: 进口管道壁厚
A6: 1200004 | B6: D2 | C6: 出口管道规格
A7: 1200005 | B7: D2w | C7: 出口管道外径
A8: 1200006 | B8: D2T | C8: 出口管道壁厚
B9: 工艺参数
A10: 1200007 | C10: 流体属性 | D10: 液体
A11: 1000007 | B11: T | C11: 介质温度 | D11: 50 | E11: 液体温度不能高于饱和温度，否则会报错
A12: 1200008 | D12: ℃
A13: 1000009 | B13: Q | C13: 气体、液体、蒸汽流量 | D13: 100
A14: 1200010 | D14: m3/h
A15: 1000011 | C15: 两相流气体或蒸汽流量换算
A16: 1200012 | D16: Nm3/h
A17: 1000013 | B17: P1 | C17: 阀前压力 | D17: 2
A18: 1200014 | D18: MPa(G)
A19: 1000015 | B19: P2 | C19: 阀后压力 | D19: 0.1
A20: 1200014 | D20: =D18 -> MPa(G)
A21: 1000016 | B21: ΔP | C21: 阀前后压差 | D21: =D17-D19 -> 1.9
A22: 1200014 | D22: =D18 -> MPa(G)
A23: 1000017 | B23: ρ | C23: 气体、液体、蒸汽、两相流液 体密度 | D23: 988
A24: 1200018 | D24: Kg/m3
A25: 1000019 | C25: 两相流气体（蒸汽） 密度
A26: 1200018 | D26: Kg/Nm3
B27: ρ/ρ0 | C27: 相对密度（比重） | D27: =IF(OR(D10="液体",D10="两相流(液体+气体)",D10="两相流(液体+蒸汽)"),D192/1000,"") -> 0.988
A28: 1000021 | B28: M | C28: 分子量
A29: 1000022 | B29: Z | C29: 压缩系数 | D29: 1
A30: 1000023 | B30: γ | C30: 比热比系数 | D30: 1.4 | E30: 空气默认1.4
B31: 粘度 | C31: 运动粘度 v 动力粘度 u | D31: 粘度
A32: 1000025 | D32: 1 | E32: 未提供参数时，需要设置默认值，或含20℃的水1.005*10-6mPa.S
A33: 1200026 | D33: cP
A34: 1200027 | B34: PC | C34: 绝对热力学临界压力 | D34: 22.12 | E34: 水为22.12
B35: Pr | C35: 对比压力 | D35: =D200/D34 -> 94.936709
A36: 1000028 | B36: Pv | C36: 入口温度下液体蒸汽的绝对压力 | D36: =IF(D18="MPa(G)",(D209-100)/1000,IF(D18="MPa(A)",D209/1000,IF(D18="KPa(G)",D209-100,IF(D18="KPa(A)",D209,IF(D18="bar(G)",(D209-100)/100,IF(D18="bar(A)",D209/100,)))))) -> -0.087672305 | E36: 介质为水的时候自动计算，其它介质为输入项
B37: T1 | C37: 入口绝对温度 | D37: =IF(D12="℃",D211+273.15,IF(D12="K",D211,IF(D12="F",D211+273.15))) -> 323.15
A38: 1200029 | B38: t | C38: 液体饱和温度 | D38: =D210 -> 214.75249 | E38: 介质为水的时候自动计算，其它介质为输入项
B39: 阀门参数
A40: 1200030 | B40: DN | C40: 阀门口径 | D40: 150
...

Sheet 气体噪音计算
A1: 符号 | B1: 名称 | C1: 单位 | D1: 公式 | E1: 结果
A2: 输出结果 | B2: 距离阀门1m处噪音 | C2: dBA | E2: =IF(E85<0.3,E98+10,E122-10) -> #NUM!
A3: 输入参数 | G3: `
A4: A | B4: 单流体面积 | C4: m2 | D4: 设计给定 | E4: 0.00137 | F4: 需要数据库，重要参数
A5: An | B5: 给定行程下n级的多级降压阀内件的最后一级的总流通面积 | C5: m2 | D5: 设计给定 | E5: =6.44*10^-3 -> 0.00644 | F5: 需要数据库，重要参数
A6: C | B6: 流量系数（计算Kv） | C6: Kv | D6: 设计给定 | E6: =Kv计算!D52 -> 24.168241
A7: D | B7: 阀门出口直径 | C7: m | D7: 设计给定 | E7: =Kv计算!D40/1000 -> 0.15
A8: d | B8: 流路直径（非圆截面则用dH）打孔直径 | C8: m | D8: 设计给定 | E8: 0.003 | F8: 需要数据库，重要参数
A9: di | B9: 阀门出口内径或渐缩管进口内径的较小值 | C9: m | D9: 设计给定 | E9: =E7 -> 0.15
A10: Di | B10: 下游管道内径 | C10: m | D10: 设计给定 | E10: =Kv计算!D126/1000 -> 0.15
A11: FL | B11: 液体压力恢复系数 | C11: 无量纲 | D11: 设计给定 | E11: =Kv计算!D42 -> 0.9
A12: FLn | B12: 低噪音阀内件最后一级的液体压力恢复系数 | C12: 无量纲 | D12: 设计给定
A13: FLp | B13: 带附接管件控制阀的液体压力恢复系数和管道 几何形状系数的复合系数 | C13: 无量纲 | D13: 设计给定 | E13: =Kv计算!D87 -> 0.9
A14: Fp | B14: 管道几何形状系数 | C14: 无量纲 | D14: 设计给定 | E14: =Kv计算!D86 -> 1
A15: l | B15: 径向流路的长度 （阀笼壁厚） | C15: m | D15: 设计给定 | E15: 0.03 | F15: 需要数据库，重要参数
A16: lw | B16: 单流路湿周 （周长） | C16: m | D16: 设计给定 | E16: 0.181 | F16: 需要数据库，重要参数
A17: M | B17: 流体分子质量 | C17: Kg/kmol | D17: 设计给定 | E17: 19.8 | F17: 需要数据库，重要参数
A18: m | B18: 质量流量 | C18: Kg/s | D18: 设计给定 | E18: =IF(Kv计算!D10="气体",Kv计算!D186/3600,IF(Kv计算!D10="蒸汽",Kv计算!D187/3600,)) -> 0
A19: ms | B19: 声速时的质量流量 | C19: Kg/s | D19: 设计给定
A20: N14 | B20: 数字常数 | C20: 无量纲 | D20: 设计给定 | E20: 0.0049
A21: N16 | B21: 数字常数 | C21: 无量纲 | D21: 设计给定 | E21: 42300
A22: No | B22: 阀内件上互相独立且完全相等的流路数 | C22: Pa(A) | D22: 设计给定 | E22: 6 | F22: 需要数据库，重要参数
A23: Pa | B23: 管道外实际大气压 | C23: Pa(A) | D23: 设计给定 | E23: 101325
A24: Po | B24: 参比声压=2x10-5（注5） | C24: Pa(A) | D24: 设计给定 | E24: 2e-05
A25: Ps | B25: 标准大气压 | C25: Pa(A) | D25: 设计给定 | E25: 101325
A26: P1 | B26: 阀入口绝对压力 | C26: Pa(A) | D26: 设计给定 | E26: =Kv计算!D200*1000 -> 2100000
A27: P2 | B27: 阀出口绝对压力 | C27: Pa(A) | D27: 设计给定 | E27: =Kv计算!D201*1000 -> 200000
A28: R | B28: 气体常数8314 | C28: J/kmol.K | D28: 设计给定 | E28: 8314
A29: Tn | B29: n级的多级降压阀内件的最后一级的绝对温度 | C29: K
A30: T1 | B30: 入口绝对温度 | C30: K | D30: 设计给定 | E30: =Kv计算!D37 -> 323.15
A31: T2 | B31: 出口绝对温度 | C31: K | D31: 设计给定 | E31: =E30 -> 323.15
A32: tp | B32: 管道壁厚 | C32: m | D32: 设计给定 | E32: =Kv计算!D130/1000 -> 0.00711
A33: Wo | B33: 参比声功率=10-12（见注5） | C33: W | E33: 1e-12
A34: β | B34: 阀出口或渐扩管入口收缩系数 | C34: 无量纲 | D34: 设计给定 | E34: 0.93
A35: γ | B35: 比热比 | C35: 无量纲 | D35: 设计给定 | E35: =Kv计算!D30 -> 1.4
A36: ρ1 | B36: P1和T1时流体密度 | C36: Kg/m3 | D36: 设计给定 | E36: =Kv计算!D198 -> 988
A37: Φ | B37: 相对流量系数 | C37: 无量纲 | D37: 设计给定 | E37: =IF(Kv计算!D10="气体",Kv计算!D54,"")
A38: 公用计算部分 | D38: 阀内件形式 | E38: 标准型
A39: Pvc | B39: 亚音速流条件下缩流断面的绝对压力 | C39: Pa(A) | E39: =E26-(E26-E27)/E11^2 -> -245679.01
A40: Pvcc | B40: 临界流条件下缩流断面的绝对压力 | C40: Pa(A) | E40: =E26*(2/(E35+1))^(E35/(E35-1)) -> 1109391.8
...

Sheet 液体噪音计算
A1: 符号 | B1: 项目名称 | C1: 单位 | D1: 公式 | E1: 结果
B2: 输出结果 | C2: dBA（±5） | D2: 距离阀门1m处噪音值 | E2: =IF(E3="闪蒸","",E69) -> 62.937961
B3: 流体状态 | E3: =IF(E28<=E37,"无气蚀",IF(AND(E37<E28,E28<=E29),"初始气蚀",IF(AND(E28>E29,E28<=1),"空化",IF(E28>1,"闪蒸")))) -> 空化
A4: 阀门
D5: 阀内件形式 | E5: 标准型
A6: Kv | B6: 所需流量系数(计算Cv) | D6: 设计给定 | E6: =Kv计算!D52 -> 24.168241
A7: m | B7: 质量流量 | C7: kg/s | D7: 设计给定 | E7: =Kv计算!D182/3600 -> 27.444444
A8: P1 | B8: 阀门入口绝对压力 | C8: Pa(A) | D8: 设计给定 | E8: =Kv计算!D200*1000 -> 2100000
A9: P2 | B9: 阀门出口绝对压力 | C9: Pa(A) | D9: 设计给定 | E9: =Kv计算!D201*1000 -> 200000
A10: d | B10: 阀入口内径 | C10: m | D10: 设计给定 | E10: =Kv计算!D40/1000 -> 0.15
A11: d0 | B11: 阀座直径 | C11: m | D11: 设计给定 | E11: =Kv计算!D118/1000 -> 0.15
A12: dH | B12: 小孔直径 | C12: m | D12: 设计给定 | E12: 0.003 | F12: 需要数据库
A13: No | B13: 小孔数量 | C13: 个 | D13: 设计给定 | E13: 120
A14: FL | B14: 压力恢复系数 | D14: 设计给定 | E14: 0.9
A15: Fd | B15: 阀门修正系数 | D15: 设计给定 | E15: =Kv计算!D132 -> 0.42 | F15: 补充计算方法
A16: 管道
A17: Di | B17: 下游管道内径 | C17: m | D17: 设计给定 | E17: =Kv计算!D128/1000 -> 0.1683
A18: tp | B18: 管壁厚度 | C18: m | D18: 设计给定 | E18: =Kv计算!D130/1000 -> 0.00711
A19: ρp | B19: 钢材的密度 | C19: kg/m³ | D19: 设计给定 | E19: 7800
A20: cp | B20: 管壁上纵向波的声速 | C20: m/s | D20: 设计给定 | E20: 5000
A21: 其他
A22: ρL | B22: 液体密度 | C22: kg/m³ | D22: 设计给定 | E22: =Kv计算!D192 -> 988
A23: Pv | B23: 液体蒸气压 | C23: Pa(A) | D23: 设计给定 | E23: =Kv计算!D209*1000 -> 12327.695
A24: cL | B24: 液体中声速 | C24: m/s | D24: 设计给定 | E24: 1400
A25: ρ0 | B25: 空气密度 | C25: kg/m³ | D25: 设计给定 | E25: 1.293
A26: c0 | B26: 空气中声速 | C26: m/s | D26: 设计给定 | E26: 343
A27: 计算
A28: xF | B28: 压差比 | E28: =(E8-E9)/(E8-E23) -> 0.91010452
A29: XFid | D29: 设计给点 | E29: =E14^2 -> 0.81
A30: △Pc | B30: Uvc压差(取两者小值) | C30: Pa(A) | E30: =E28*(E8-E23) -> 1900000
E31: =E14^2*(E8-E23) -> 1691014.6
D32: △Pc取最小值 | E32: =MIN(E30:E31) -> 1691014.6
A33: N34 | D33: 设计给定 | E33: 1
A34: N14 | D34: 设计给定 | E34: 0.0049
A35: xFz | B35: 初生空化噪声压差比 用于多级阀之外的模型 | E35: =0.9/SQRT(1+3*E15*SQRT(E6/(E33*E14))) -> 0.32799178
B36: 初生空化噪声压差比 用于多级阀的模型 | E36: =1/SQRT(4.5+1650*E13*E12^2/E14) -> 0.3928371
D37: 结果判定 | E37: =IF(E5="标准型",E35,IF(E5="多级降压",E36)) -> 0.32799178
A38: xFzp1 | B38: 修正入口压力的压差比 | E38: =E37*(6*10^5/E8)^0.125 -> 0.28044936
A39: Dj | B39: 射流直径 | C39: m | E39: =E34*E15*(E6*E14)^0.5 -> 0.0095981856
A40: Uvc | B40: 缩流断面处流速 | C40: m/s | E40: =1/E14*((2*E32)/E22)^0.5 -> 65.008133
...

Sheet 管道规格表
A1: 管道规格表
A2: 通径 | C2: 外径 | E2: SCH壁厚等级
A3: 英制 | B3: 公制 | C3: 英制 | D3: 公制 | E3: 10 | F3: 20 | G3: 30 | H3: 40 | I3: 60 | J3: 80 | K3: 100 | L3: 120 | M3: 140 | N3: 160 | O3: STD | P3: XS | Q3: XXS | R3: 5S | S3: 10S | T3: 20S | U3: 40S | V3: 80S
A4: 1/8 | B4: 6 | C4: 10.3 | H4: 1.73 | J4: 2.41 | O4: 1.73 | P4: 2.41 | S4: 1.24 | U4: 1.73 | V4: 2.41
A5: 1/4 | B5: 8 | C5: 13.7 | H5: 2.24 | J5: 3.02 | O5: 2.24 | P5: 3.02 | S5: 1.65 | U5: 2.24 | V5: 3.02
A6: 3/8 | B6: 10 | C6: 17.2 | D6: 14 | H6: 2.31 | J6: 3.32 | O6: 2.31 | P6: 3.32 | S6: 1.65 | T6: 2 | U6: 2.31 | V6: 3.2
A7: 1/2 | B7: 15 | C7: 21.3 | D7: 18 | H7: 2.77 | J7: 3.73 | N7: 4.78 | O7: 2.77 | P7: 3.73 | Q7: 7.47 | R7: 1.65 | S7: 2.11 | T7: 2.5 | U7: 2.77 | V7: 3.73
A8: 3/4 | B8: 20 | C8: 26.9 | D8: 25 | H8: 2.87 | J8: 3.91 | N8: 5.56 | O8: 2.87 | P8: 3.91 | Q8: 7.82 | R8: 1.65 | S8: 2.11 | T8: 2.5 | U8: 2.87 | V8: 3.91
A9: 1 | B9: 25 | C9: 33.7 | D9: 32 | H9: 3.38 | J9: 4.55 | N9: 6.35 | O9: 3.38 | P9: 4.55 | Q9: 9.09 | R9: 1.65 | S9: 2.77 | T9: 3 | U9: 3.38 | V9: 4.55
A10: 1-1/4 | B10: 32 | C10: 42.4 | D10: 38 | H10: 3.56 | J10: 4.85 | N10: 6.35 | O10: 3.56 | P10: 4.85 | Q10: 9.7 | R10: 1.65 | S10: 2.77 | T10: 3 | U10: 3.56 | V10: 4.85
A11: 1-1/2 | B11: 40 | C11: 48.3 | D11: 45 | H11: 3.68 | J11: 5.08 | N11: 7.14 | O11: 3.68 | P11: 5.08 | Q11: 10.15 | R11: 1.65 | S11: 2.77 | T11: 3 | U11: 3.68 | V11: 5.08
A12: 2 | B12: 50 | C12: 60.3 | D12: 57 | H12: 3.91 | J12: 5.54 | N12: 8.74 | O12: 3.91 | P12: 5.54 | Q12: 11.07 | R12: 1.65 | S12: 2.77 | T12: 3.5 | U12: 3.91 | V12: 5.54
A13: 2-1/2 | B13: 65 | C13: 76.1 | D13: 76 | H13: 5.16 | J13: 7.01 | N13: 9.53 | O13: 5.16 | P13: 7.01 | Q13: 14.02 | R13: 2.11 | S13: 3.05 | T13: 3.5 | U13: 5.16 | V13: 7.01
A14: 3 | B14: 80 | C14: 88.9 | D14: 89 | H14: 5.49 | J14: 7.62 | N14: 11.13 | O14: 5.49 | P14: 7.62 | Q14: 15.24 | R14: 2.11 | S14: 3.05 | T14: 4 | U14: 5.49 | V14: 7.62
A15: 3-1/2 | B15: 90 | C15: 101.6 | D15: - | H15: 5.74 | J15: 8.08 | O15: 5.74 | P15: 8.08 | R15: 2.11 | S15: 3.05 | U15: 5.74 | V15: 8.08
A16: 4 | B16: 100 | C16: 114.3 | D16: 108 | H16: 6.02 | J16: 8.56 | L16: 11.13 | N16: 13.49 | O16: 6.02 | P16: 8.56 | Q16: 17.12 | R16: 2.11 | S16: 3.05 | T16: 4 | U16: 6.02 | V16: 8.56
A17: 5 | B17: 125 | C17: 139.7 | D17: 133 | H17: 6.55 | J17: 9.53 | L17: 12.7 | N17: 15.88 | O17: 6.55 | P17: 9.53 | Q17: 19.05 | R17: 2.77 | S17: 3.4 | T17: 5 | U17: 6.55 | V17: 9.53
A18: 6 | B18: 150 | C18: 168.3 | D18: 159 | H18: 7.11 | J18: 10.97 | L18: 14.27 | N18: 18.26 | O18: 7.11 | P18: 10.97 | Q18: 21.95 | R18: 2.77 | S18: 3.4 | T18: 5 | U18: 7.11 | V18: 10.97
A19: 8 | B19: 200 | C19: 219.1 | D19: 219 | F19: 6.35 | G19: 7.04 | H19: 8.18 | I19: 10.31 | J19: 12.7 | K19: 15.09 | L19: 18.26 | M19: 20.62 | N19: 23.01 | O19: 8.18 | P19: 12.7 | Q19: 22.23 | R19: 2.77 | S19: 3.76 | T19: 6.5 | U19: 8.18 | V19: 12.7
A20: 10 | B20: 250 | C20: 273 | D20: 273 | F20: 6.35 | G20: 7.8 | H20: 9.27 | I20: 12.7 | J20: 15.09 | K20: 18.26 | L20: 21.44 | M20: 25.4 | N20: 28.58 | O20: 9.27 | P20: 12.7 | Q20: 25.4 | R20: 3.4 | S20: 4.19 | T20: 6.5 | U20: 9.27 | V20: 12.7
A21: 12 | B21: 300 | C21: 323.9 | D21: 325 | F21: 6.35 | G21: 8.38 | H21: 10.31 | I21: 14.27 | J21: 17.48 | K21: 21.44 | L21: 25.4 | M21: 28.58 | N21: 33.32 | O21: 9.53 | P21: 12.7 | Q21: 25.4 | R21: 3.96 | S21: 4.57 | T21: 6.5 | U21: 9.53 | V21: 12.7
A22: 14 | B22: 350 | C22: 355.6 | D22: 377 | E22: 6.35 | F22: 7.92 | G22: 9.53 | H22: 11.13 | I22: 15.09 | J22: 19.05 | K22: 23.83 | L22: 27.79 | M22: 31.75 | N22: 35.71 | O22: 9.53 | P22: 12.7 | R22: 3.96 | S22: 4.78 | U22: 9.53 | V22: 12.7
A23: 16 | B23: 400 | C23: 406.4 | D23: 426 | E23: 6.35 | F23: 7.92 | G23: 11.13 | H23: 12.27 | I23: 16.66 | J23: 21.44 | K23: 26.19 | L23: 30.96 | M23: 36.53 | N23: 40.49 | O23: 9.53 | P23: 12.7 | R23: 4.19 | S23: 4.78 | U23: 9.53 | V23: 12.7
A24: 18 | B24: 450 | C24: 457 | D24: 480 | E24: 6.35 | F24: 7.92 | G24: 12.7 | H24: 14.27 | I24: 19.05 | J24: 23.83 | K24: 29.36 | L24: 34.93 | M24: 39.68 | N24: 45.24 | O24: 9.53 | P24: 12.7 | R24: 4.19 | S24: 4.783 | U24: 9.53 | V24: 12.7
A25: 20 | B25: 500 | C25: 508 | D25: 530 | E25: 6.35 | F25: 9.53 | G25: 12.7 | H25: 15.09 | I25: 20.62 | J25: 26.19 | K25: 32.54 | L25: 38.1 | M25: 44.45 | N25: 50.01 | O25: 9.53 | P25: 12.7 | R25: 4.78 | S25: 5.54 | U25: 9.53 | V25: 12.7
A26: 22 | B26: 550 | C26: 559 | D26: - | E26: 6.35 | F26: 9.53 | G26: 14.27 | H26: 15.88 | I26: 22.23 | J26: 28.58 | K26: 34.93 | L26: 41.28 | M26: 47.63 | N26: 53.98 | O26: 9.53 | P26: 12.7 | R26: 4.78 | S26: 5.54 | U26: 9.53 | V26: 12.7
A27: 24 | B27: 600 | C27: 610 | D27: 630 | E27: 6.35 | F27: 9.53 | H27: 17.45 | I27: 24.61 | J27: 30.96 | K27: 38.89 | L27: 46.02 | M27: 52.37 | N27: 59.54 | O27: 9.53 | P27: 12.7 | R27: 5.54 | U27: 9.53 | V27: 12.7
A28: 26 | B28: 650 | C28: 660 | D28: - | E28: 7.92 | F28: 12.7 | G28: 15.88 | O28: 9.53 | P28: 12.7
A29: 28 | B29: 700 | C29: 711 | D29: 720 | E29: 7.92 | F29: 12.7 | G29: 15.88 | O29: 9.53 | P29: 12.7
A30: 30 | B30: 750 | C30: 762 | D30: - | E30: 7.92 | F30: 12.7 | G30: 15.88 | O30: 9.53 | P30: 12.7 | S30: 7.92
A31: 32 | B31: 800 | C31: 813 | D31: 820 | E31: 7.92 | F31: 12.7 | G31: 15.88 | H31: 17.48 | O31: 9.53 | P31: 12.7
A32: 34 | B32: 850 | C32: 864 | D32: - | E32: 7.92 | F32: 12.7 | G32: 15.88 | H32: 17.48 | O32: 9.53 | P32: 12.7
A33: 36 | B33: 900 | C33: 914 | D33: 920 | E33: 7.92 | F33: 12.7 | G33: 15.88 | H33: 19.05 | O33: 9.53 | P33: 12.7
A34: 38 | B34: 950 | C34: 965 | D34: - | O34: 9.53 | P34: 12.7
A35: 40 | B35: 1000 | C35: 1016 | D35: 1020 | O35: 9.53 | P35: 12.7
A36: 42 | B36: 1050 | C36: 1067 | D36: - | O36: 9.53 | P36: 12.7
A37: 44 | B37: 1100 | C37: 1118 | D37: 1120 | O37: 9.53
A38: 46 | B38: 1150 | C38: 1168 | D38: -
A39: 48 | B39: 1200 | C39: 1219 | D39: 1220
